<?xml version="1.0" ?>
<robot xmlns:xacro="http://ros.org/wiki/xacro">

<xacro:macro name="comau_ns16arc" params="prefix">

  <link name="${prefix}base_link">
    <visual>
      <origin 
        xyz="0 0 0"
        rpy="0 0 0" />
      <geometry>
        <mesh
          filename="package://comau_ns16arc_support/meshes/base_link.STL" />
      </geometry>
      <material
        name="Red">
        <color
          rgba="1 0 0 1" />
      </material>
    </visual>
    <collision>
      <origin
        xyz="0 0 0"
        rpy="0 0 0" />
      <geometry>
        <mesh
          filename="package://comau_ns16arc_support/meshes/base_link.STL" />
      </geometry>
    </collision>
  </link>
  <link
    name="Link_1">
    <inertial>
      <origin
        xyz="0.092687 0.0098815 -0.17643"
        rpy="0 0 0" />
      <mass
        value="295.32" />
      <inertia
        ixx="5.9793"
        ixy="0.12844"
        ixz="-1.8884"
        iyy="9.5747"
        iyz="-0.45474"
        izz="8.0459" />
    </inertial>
    <visual>
      <origin
        xyz="0 0 0"
        rpy="0 0 0" />
      <geometry>
        <mesh
          filename="package://comau_ns16arc_support/meshes/Link_1.STL" />
      </geometry>
      <material
        name="">
        <color
          rgba="1 0 0 1" />
      </material>
    </visual>
    <collision>
      <origin
        xyz="0 0 0"
        rpy="0 0 0" />
      <geometry>
        <mesh
          filename="package://comau_ns16arc_support/meshes/Link_1.STL" />
      </geometry>
    </collision>
  </link>
  <joint name="${prefix}Joint_1" type="revolute">
    <origin xyz="0 0 0.251" rpy="-3.1416 0 0" />
    <parent link="base_link" />
    <child link="Link_1" />
    <axis xyz="0 0 1" />
    <limit effort="0" lower="-3.14159" upper="3.14159"  velocity="0" />
  </joint>
  <link
    name="Link_2">
    <inertial>
      <origin
        xyz="0.012589 0.28782 -0.10477"
        rpy="0 0 0" />
      <mass
        value="58.959" />
      <inertia
        ixx="3.913"
        ixy="0.07732"
        ixz="-0.024978"
        iyy="0.47847"
        iyz="-0.39274"
        izz="3.9572" />
    </inertial>
    <visual>
      <origin
        xyz="0 0 0"
        rpy="0 0 0" />
      <geometry>
        <mesh
          filename="package://comau_ns16arc_support/meshes/Link_2.STL" />
      </geometry>
      <material
        name="">
        <color
          rgba="1 0 0 1" />
      </material>
    </visual>
    <collision>
      <origin
        xyz="0 0 0"
        rpy="0 0 0" />
      <geometry>
        <mesh
          filename="package://comau_ns16arc_support/meshes/Link_2.STL" />
      </geometry>
    </collision>
  </link>
  <joint
    name="Joint_2"
    type="revolute">
    <origin
      xyz="0.3 0.101 -0.349"
      rpy="-1.5708 0 3.1416" />
    <parent
      link="Link_1" />
    <child
      link="Link_2" />
    <axis
      xyz="0 0 1" />
    <limit effort="0" lower="-0.87266" upper="1.658" velocity="0" />
  </joint>
  <link
    name="Link_3">
    <inertial>
      <origin
        xyz="0.081754 0.13848 -0.077319"
        rpy="0 0 0" />
      <mass
        value="127.93" />
      <inertia
        ixx="2.6486"
        ixy="0.38607"
        ixz="-0.293"
        iyy="1.6625"
        iyz="-0.60693"
        izz="2.2741" />
    </inertial>
    <visual>
      <origin
        xyz="0 0 0"
        rpy="0 0 0" />
      <geometry>
        <mesh
          filename="package://comau_ns16arc_support/meshes/Link_3.STL" />
      </geometry>
      <material
        name="">
        <color
          rgba="1 0 0 1" />
      </material>
    </visual>
    <collision>
      <origin
        xyz="0 0 0"
        rpy="0 0 0" />
      <geometry>
        <mesh
          filename="package://comau_ns16arc_support/meshes/Link_3.STL" />
      </geometry>
    </collision>
  </link>
  <joint name="${prefix}Joint_3" type="revolute">
    <origin xyz="0 0.7 0" rpy="3.1416 0 1.5708" />
    <parent link="Link_2" />
    <child link="Link_3" />
    <axis xyz="0 0 1" />
    <limit effort="0"  lower="-2.967" upper="1.9198" velocity="0" />
  </joint>
  <link
    name="Link_4">
    <inertial>
      <origin
        xyz="-4.3765E-06 -0.01007 -0.27556"
        rpy="0 0 0" />
      <mass
        value="37.589" />
      <inertia
        ixx="0.65662"
        ixy="-3.6419E-06"
        ixz="-2.0413E-05"
        iyy="0.54018"
        iyz="0.026907"
        izz="0.177" />
    </inertial>
    <visual>
      <origin
        xyz="0 0 0"
        rpy="0 0 0" />
      <geometry>
        <mesh
          filename="package://comau_ns16arc_support/meshes/Link_4.STL" />
      </geometry>
      <material
        name="">
        <color
          rgba="1 0 0 1" />
      </material>
    </visual>
    <collision>
      <origin
        xyz="0 0 0"
        rpy="0 0 0" />
      <geometry>
        <mesh
          filename="package://comau_ns16arc_support/meshes/Link_4.STL" />
      </geometry>
    </collision>
  </link>
  <joint
    name="Joint_4"
    type="revolute">
    <origin
      xyz="0.238 0.185 -0.101"
      rpy="-1.5708 0 1.5708" />
    <parent
      link="Link_3" />
    <child
      link="Link_4" />
    <axis
      xyz="0 0 1" />
    <limit effort="0" lower="-6.2831853" upper="6.2831853" velocity="0" />
  </joint>
  <link
    name="Link_5">
    <inertial>
      <origin
        xyz="0.053501 -2.0551E-05 -0.0011681"
        rpy="0 0 0" />
      <mass
        value="5.6467" />
      <inertia
        ixx="0.0051083"
        ixy="6.1292E-06"
        ixz="0.00019799"
        iyy="0.011737"
        iyz="4.2034E-06"
        izz="0.011695" />
    </inertial>
    <visual>
      <origin
        xyz="0 0 0"
        rpy="0 0 0" />
      <geometry>
        <mesh
          filename="package://comau_ns16arc_support/meshes/Link_5.STL" />
      </geometry>
      <material
        name="">
        <color
          rgba="0.50196 0.50196 0.50196 1" />
      </material>
    </visual>
    <collision>
      <origin
        xyz="0 0 0"
        rpy="0 0 0" />
      <geometry>
        <mesh
          filename="package://comau_ns16arc_support/meshes/Link_5.STL" />
      </geometry>
    </collision>
  </link>
  <joint
    name="Joint_5"
    type="revolute">
    <origin
      xyz="0 0 -0.386"
      rpy="-1.5708 1.5708 0" />
    <parent
      link="Link_4" />
    <child
      link="Link_5" />
    <axis
      xyz="0 0 1" />
    <limit effort="0" lower="-3.14159" upper="3.14159" velocity="0" />
  </joint>
  <link
    name="Link_6">
    <inertial>
      <origin
        xyz="-0.0022013 2.0382E-05 -0.017234"
        rpy="0 0 0" />
      <mass
        value="1.2001" />
      <inertia
        ixx="0.00098201"
        ixy="5.385E-08"
        ixz="-7.915E-06"
        iyy="0.00086572"
        iyz="3.5423E-07"
        izz="0.0017201" />
    </inertial>
    <visual>
      <origin
        xyz="0 0 0"
        rpy="0 0 0" />
      <geometry>
        <mesh
          filename="package://comau_ns16arc_support/meshes/Link_6.STL" />
      </geometry>
      <material
        name="">
        <color  
          rgba="0.25098 0.25098 0.25098 1" />
      </material>
    </visual>
    <collision>
      <origin
        xyz="0 0 0"
        rpy="0 0 0" />
      <geometry>
        <mesh
          filename="package://comau_ns16arc_support/meshes/Link_6.STL" />
      </geometry>
    </collision>
  </link>
  <joint
    name="Joint_6"
    type="revolute">
    <origin
      xyz="0.106 0 0"
      rpy="1.5708 0 -1.5708" />
    <parent
      link="Link_5" />
    <child
      link="Link_6" />
    <axis
      xyz="0 0 1" />
    <limit effort="0" lower="-6.2831853" upper="6.2831853" velocity="0" />
  </joint>
  <link name="${prefix}Flange" />
  <joint name="${prefix}Flange_fixed" type="fixed">
    <origin xyz="0 0 -0.014" rpy="3.1416 0 3.1416" />
    <parent link="Link_6" />
    <child link="Flange" />
    <axis xyz="0 0 0" />
  </joint>
  <link name="${prefix}ee_link" />
  <joint name="${prefix}ee_link_fixed" type="fixed">
    <origin xyz="0.304083 0.002668 0.232848" rpy="0 0 1.570796326794897" />
    <parent link="Flange" />
    <child link="ee_link" />
    <axis xyz="0 0 0" />
  </joint>
  
  
  <link name="${prefix}base"/>
  <joint name="${prefix}base_link-base_fixed_joint" type="fixed">
    <origin rpy="0 0 -3.14159265" xyz="0 0 0"/>
    <parent link="base_link"/>
    <child link="base"/>
  </joint>

</xacro:macro>
</robot>
